Workbook

Sheet Template
A1: Columns | B1: Status | C1: Error Message | D1: Action | E1: ProjectNumber | F1: ProjectName | H1: ProjectStatusCode | I1: LegalEntityName | K1: OwningOrganizationName | M1: SourceTemplateName | O1: AllowCapitalizedInterestFlag | P1: AssetAllocationMethodCode | Q1: BurdenScheduleName | R1: BurdenScheduleFixedDate | S1: CapitalEventProcessingMethodCode | T1: CIntRateSchName | U1: CIntStopDate | V1: ProjectCurrencyCode | W1: CurrencyConvDate | X1: CurrencyConvRateType | Y1: CurrencyConvDateTypeCode | Z1: IncludeNotesInKPINotificationsFlag | AA1: KPINotificationEnabledFlag | AB1: PlanningProjectFlag | AC1: AllowCrossChargeFlag | AD1: TaskName | AE1: ExternalTaskId | AF1: ExternalParentTaskId | AG1: ElementType | AH1: ExpenseResourceName | AI1: LaborResourceName | AJ1: LaborResourceEmail | AK1: LaborPrimaryResource | AL1: RuleNumber | AM1: Billable | AN1: Chargeable | AO1: ExternalPredecessorTaskId | AP1: ExternalTaskId | AQ1: Lag | AR1: DependencyType | AS1: PersonEmail | AT1: ProjectRole | AU1: StartDate | AV1: ClassCategory | AW1: ClassCode | AX1: CodePercentage | AY1: OpportunityNumber | AZ1: OpportunityName | BA1: OpportunityAmount | BB1: OpportunityCustomerName | BC1: OpportunityCustomerNumber | BD1: OpportunityStatus | BE1: OpportunityWinConfPercent | BF1: PartyName | BG1: PartyNumber | BH1: BusinessUnitName | BI1: CategoryName | BJ1: DatatypeCode | BK1: FileContents | BL1: Title | BM1: FileName | BN1: ProjectEndDate | BO1: ProjectStartDate | BP1: crmNumber | BQ1: supplierPaymentProcess | BR1: supplierPaymentProcess_Display | BS1: domain | BT1: marketSegment | BU1: domain_Display | BV1: marketSegment_Display | BW1: specificities | BX1: specificities_Display | BY1: fundingSource | BZ1: fundingSource_Display | CA1: subFundingSource | CB1: subFundingSource_Display | CC1: procedures | CD1: procedures_Display | CE1: countryDestinationView | CF1: stateOrProvince | CG1: TaskFinishDate | CH1: TaskNumber | CI1: TaskStartDate | CJ1: ObjectType | CK1: ElementType
A2: Status | B2: Technical | C2: Technical | D2: Action | E2: Header | F2: Header | H2: Header | I2: Header | K2: Header | M2: Header | O2: Header | P2: Header | Q2: Header | R2: Header | S2: Header | T2: Header | U2: Header | V2: Header | W2: Header | X2: Header | Y2: Header | Z2: Header | AA2: Header | AB2: Header | AC2: Header | AD2: Tasks | AE2: Tasks | AF2: Tasks | AG2: Tasks | AH2: ExpenseResourceAssignments | AI2: LaborResourceAssignments | AJ2: LaborResourceAssignments | AK2: LaborResourceAssignments | AL2: TaskTransactionControls | AM2: TaskTransactionControls | AN2: TaskTransactionControls | AO2: TaskDependencies | AP2: TaskDependencies | AQ2: TaskDependencies | AR2: TaskDependencies | AS2: ProjectTeamMembers | AT2: ProjectTeamMembers | AU2: ProjectTeamMembers | AV2: ProjectClassifications | AW2: ProjectClassifications | AX2: ProjectClassifications | AY2: ProjectOpportunities | AZ2: ProjectOpportunities | BA2: ProjectOpportunities | BB2: ProjectOpportunities | BC2: ProjectOpportunities | BD2: ProjectOpportunities | BE2: ProjectOpportunities | BF2: ProjectCustomers | BG2: ProjectCustomers | BH2: ProviderBusinessUnits | BI2: Attachments | BJ2: Attachments | BK2: Attachments | BL2: Attachments | BM2: Attachments | BN2: Header | BO2: Header | BP2: Header | BQ2: Header | BR2: Header | BS2: Header | BT2: Header | BU2: Header | BV2: Header | BW2: Header | BX2: Header | BY2: Header | BZ2: Header | CA2: Header | CB2: Header | CC2: Header | CD2: Header | CE2: Header | CF2: Header | CG2: Tasks | CH2: Tasks | CI2: Tasks | CJ2: Tasks | CK2: Tasks
A3: Type | B3: Standard | C3: Standard | D3: Standard | E3: Standard | F3: Standard | H3: Standard | I3: Standard | K3: Standard | M3: Standard | O3: Standard | P3: Standard | Q3: Standard | R3: Standard | S3: Standard | T3: Standard | U3: Standard | V3: Standard | W3: Standard | X3: Standard | Y3: Standard | Z3: Standard | AA3: Standard | AB3: Standard | AC3: Standard | AD3: Standard | AE3: Standard | AF3: Standard | AG3: Standard | AH3: Standard | AI3: Standard | AJ3: Standard | AK3: Standard | AL3: Standard | AM3: Standard | AN3: Standard | AO3: Standard | AP3: Standard | AQ3: Standard | AR3: Standard | AS3: Standard | AT3: Standard | AU3: Standard | AV3: Standard | AW3: Standard | AX3: Standard | AY3: Standard | AZ3: Standard | BA3: Standard | BB3: Standard | BC3: Standard | BD3: Standard | BE3: Standard | BF3: Standard | BG3: Standard | BH3: Standard | BI3: Standard | BJ3: Standard | BK3: Standard | BL3: Standard | BM3: Standard | BN3: Standard | BO3: Standard | BP3: ProjectDFF | BQ3: ProjectDFF | BR3: ProjectDFF | BS3: ProjectDFF | BT3: ProjectDFF | BU3: ProjectDFF | BV3: ProjectDFF | BW3: ProjectDFF | BX3: ProjectDFF | BY3: ProjectDFF | BZ3: ProjectDFF | CA3: ProjectDFF | CB3: ProjectDFF | CC3: ProjectDFF | CD3: ProjectDFF | CE3: ProjectDFF | CF3: ProjectDFF | CG3: Standard | CH3: Standard | CI3: Standard | CJ3: TasksDFF | CK3: TasksDFF
A4: Custom Labels | B4: Status | C4: Error Message | D4: Action | E4: Project Number | F4: Project Name | G4: ProjectName to migrate | H4: Project Status Code | I4: Legal Entity Name | J4: Legal Entity Name to migrate | K4: Owning Organization Name | L4: Owning Organization Name to migrate | M4: Source Template Name | N4: SourceTemplateName to migrate | O4: Allow Capitalized Interest Flag | P4: Asset Allocation Method Code | Q4: Burden Schedule Name | R4: Burden Schedule Fixed Date | S4: Capital Event Processing Method Code | T4: CIntRateSchName | U4: CIntStopDate | V4: Project Currency Code | W4: Currency Conv Date | X4: Currency Conv Rate Type | Y4: Currency Conv Date Type Code | Z4: Include Notes In KPI Notifications Flag | AA4: KPI Notification Enabled Flag | AB4: Planning Project lag | AC4: Allow cross-charge transactions from other business units | AD4: Task Name | AE4: External Task Id | AF4: External Parent Task Id | AG4: Element Type | AH4: Expense Resource Name | AI4: Labor Resource Name | AJ4: Labor Resource Email | AK4: Labor Primary Resource | AL4: Rule Number | AM4: Billable | AN4: Chargeable | AO4: External Predecessor Task Id | AP4: External Task Id | AQ4: Lag | AR4: Dependency Type | AS4: Person Email | AT4: Project Role | AU4: Start Date | AV4: Class Category | AW4: Class Code | AX4: Code Percentage | AY4: Opportunity Number | AZ4: Opportunity Name | BA4: Opportunity Amount | BB4: Opportunity Customer Name | BC4: Opportunity Customer Number | BD4: Opportunity Status | BE4: Opportunity Win Conf Percent | BF4: Party Name | BG4: Party Number | BH4: BusinessUnitName | BI4: Category Name | BJ4: Data type Code | BK4: File Contents | BL4: Title | BM4: File Name | BN4: Project Finish Date | BO4: Project Start Date | CG4: Task Finish Date | CH4: Task Number | CI4: Task Start Date
B5: OK | D5: CREATE | E5: BIL-1007342 | F5: TESTUK1 | G5: ETS-BIL-1007342-TESTUK1 | H5: DRAFT | I5: EGIS UK - CONSULTING AND ENGINEERING LIMITED | J5: =_xlfn.XLOOKUP(I5,LE!A:A,LE!F:F,,1) -> 0 | K5: SL-Nuclear SL-CC-12-NTAI-21-Nuclear Technical Assistance-BU-GB03958GB_EGIS UK | L5: =_xlfn.XLOOKUP(K5,'ORG name (PPM)'!A:A,'ORG name (PPM)'!G:G,,1) -> 0 | M5: EGIS UK - CONSULTING AND ENGINEERING LIMITED Billable | N5: =_xlfn.XLOOKUP(M5,'source template'!A:A,'source template'!I:I,,1) -> 0 | V5: GBP | X5: Corporate | Y5: T | Z5: FALSE | AA5: FALSE | AB5: TRUE | AD5: Tender Costs | AE5: P01 | AG5: FINANCIAL | BN5: 47848 | BO5: 44927 | BP5: ZZZZZ | BQ5: STD | BR5: Standard | CG5: 47848 | CH5: P01 | CI5: 44927 | CJ5: PJF_TASKS | CK5: FINANCIAL
B6: OK | D6: CREATE | E6: BIL-1007342 | F6: TESTUK1 | G6: ETS-BIL-1007342-TESTUK1 | H6: DRAFT | I6: EGIS UK - CONSULTING AND ENGINEERING LIMITED | J6: =_xlfn.XLOOKUP(I6,LE!A:A,LE!F:F,,1) -> 0 | K6: SL-Nuclear SL-CC-12-NTAI-21-Nuclear Technical Assistance-BU-GB03958GB_EGIS UK | L6: =_xlfn.XLOOKUP(K6,'ORG name (PPM)'!A:A,'ORG name (PPM)'!G:G,,1) -> 0 | M6: EGIS UK - CONSULTING AND ENGINEERING LIMITED Billable | N6: =_xlfn.XLOOKUP(M6,'source template'!A:A,'source template'!I:I,,1) -> 0 | V6: GBP | X6: Corporate | Y6: T | Z6: FALSE | AA6: FALSE | AB6: TRUE | AD6: Budget | AE6: P02 | AG6: FINANCIAL | BN6: 47848 | BO6: 44927 | BP6: ZZZZZ | BQ6: STD | BR6: Standard | CG6: 47848 | CH6: P02 | CI6: 44927 | CJ6: PJF_TASKS | CK6: FINANCIAL
B7: OK | D7: CREATE | E7: BIL-1007342 | F7: TESTUK1 | G7: ETS-BIL-1007342-TESTUK1 | H7: DRAFT | I7: EGIS UK - CONSULTING AND ENGINEERING LIMITED | J7: =_xlfn.XLOOKUP(I7,LE!A:A,LE!F:F,,1) -> 0 | K7: SL-Nuclear SL-CC-12-NTAI-21-Nuclear Technical Assistance-BU-GB03958GB_EGIS UK | L7: =_xlfn.XLOOKUP(K7,'ORG name (PPM)'!A:A,'ORG name (PPM)'!G:G,,1) -> 0 | M7: EGIS UK - CONSULTING AND ENGINEERING LIMITED Billable | N7: =_xlfn.XLOOKUP(M7,'source template'!A:A,'source template'!I:I,,1) -> 0 | V7: GBP | X7: Corporate | Y7: T | Z7: FALSE | AA7: FALSE | AB7: TRUE | AD7: Non charegable to client | AE7: P03 | AG7: FINANCIAL | BN7: 47848 | BO7: 44927 | BP7: ZZZZZ | BQ7: STD | BR7: Standard | CG7: 47848 | CH7: P03 | CI7: 44927 | CJ7: PJF_TASKS | CK7: FINANCIAL
B8: OK | D8: CREATE | E8: BIL-1007342 | F8: TESTUK1 | G8: ETS-BIL-1007342-TESTUK1 | H8: DRAFT | I8: EGIS UK - CONSULTING AND ENGINEERING LIMITED | J8: =_xlfn.XLOOKUP(I8,LE!A:A,LE!F:F,,1) -> 0 | K8: SL-Nuclear SL-CC-12-NTAI-21-Nuclear Technical Assistance-BU-GB03958GB_EGIS UK | L8: =_xlfn.XLOOKUP(K8,'ORG name (PPM)'!A:A,'ORG name (PPM)'!G:G,,1) -> 0 | M8: EGIS UK - CONSULTING AND ENGINEERING LIMITED Billable | N8: =_xlfn.XLOOKUP(M8,'source template'!A:A,'source template'!I:I,,1) -> 0 | V8: GBP | X8: Corporate | Y8: T | Z8: FALSE | AA8: FALSE | AB8: TRUE | AD8: 425770 - Egis Structures and Environment - CM | AE8: P04 | AG8: FINANCIAL | BN8: 47848 | BO8: 44927 | BP8: ZZZZZ | BQ8: STD | BR8: Standard | CG8: 47848 | CH8: P04 | CI8: 44927 | CJ8: PJF_TASKS | CK8: FINANCIAL
B9: OK | D9: CREATE | E9: BIL-1007342 | F9: TESTUK1 | G9: ETS-BIL-1007342-TESTUK1 | H9: DRAFT | I9: EGIS UK - CONSULTING AND ENGINEERING LIMITED | J9: =_xlfn.XLOOKUP(I9,LE!A:A,LE!F:F,,1) -> 0 | K9: SL-Nuclear SL-CC-12-NTAI-21-Nuclear Technical Assistance-BU-GB03958GB_EGIS UK | L9: =_xlfn.XLOOKUP(K9,'ORG name (PPM)'!A:A,'ORG name (PPM)'!G:G,,1) -> 0 | M9: EGIS UK - CONSULTING AND ENGINEERING LIMITED Billable | N9: =_xlfn.XLOOKUP(M9,'source template'!A:A,'source template'!I:I,,1) -> 0 | V9: GBP | X9: Corporate | Y9: T | Z9: FALSE | AA9: FALSE | AB9: TRUE | AD9: P05 - Phase 05 | AE9: P05 | AG9: FINANCIAL | BN9: 47848 | BO9: 44927 | BP9: ZZZZZ | BQ9: STD | BR9: Standard | CG9: 47848 | CH9: P05 | CI9: 44927 | CJ9: PJF_TASKS | CK9: FINANCIAL
E10: FR03319FR-4896 | F10: 30 Logements Siguy [3319_4896] | G10: ="TESTME"&"-"&E10&"-"&F10 -> TESTME-FR03319FR-4896-30 Logements Siguy [3319_4896] | H10: ACTIVE | I10: EGIS BATIMENTS ANTILLES GUYANE | J10: =_xlfn.XLOOKUP(I10,LE!A:A,LE!F:F,,1) -> EGIS BATIMENTS ILE DE FRANCE | K10: SL-Buildings-CC-12-IDMI-01-Ile de France-BU-FR03305FR_EGIS BAT IDF | L10: SL-Buildings-CC-12-IDMI-01-Ile de France-BU-FR03305FR_EGIS BAT IDF | M10: EGIS BATIMENTS ILE DE FRANCE Billable E&SC Small Project | N10: EGIS BATIMENTS ILE DE FRANCE Billable E&SC Small Project | V10: EUR | X10: Corporate | Y10: T | Z10: FALSE | AA10: FALSE | AB10: TRUE | AC10: TRUE | AD10: O | AE10: P01 | AG10: FINANCIAL | BN10: 46203 | BO10: 41275 | BP10: 319-000008 | BQ10: STD | BR10: Standard | CG10: 45657 | CH10: P01 | CI10: 41275 | CJ10: PJF_TASKS | CK10: FINANCIAL
B11: OK | D11: CREATE | E11: BIL-1007990 | F11: TESTME-FR03319FR-BAPD25501-GUY Collège ECO-Q RM [3319_BAPD25501] | G11: TESTME-FR03319FR-BAPD25501-GUY Collège ECO-Q RM [3319_BAPD25501] | H11: DRAFT | I11: EGIS BATIMENTS ILE DE FRANCE | J11: =_xlfn.XLOOKUP(I11,LE!A:A,LE!F:F,,1) -> 0 | K11: SL-Buildings-CC-12-IDMI-01-Ile de France-BU-FR03305FR_EGIS BAT IDF | L11: SL-Buildings-CC-12-IDMI-01-Ile de France-BU-FR03305FR_EGIS BAT IDF | M11: EGIS BATIMENTS ILE DE FRANCE Billable E&SC Small Project | N11: EGIS BATIMENTS ILE DE FRANCE Billable E&SC Small Project | V11: EUR | X11: Corporate | Y11: T | Z11: FALSE | AA11: FALSE | AB11: TRUE | AC11: TRUE | AD11: O - Offre | AE11: P01 | AG11: FINANCIAL | BN11: 46387 | BO11: 43679 | BP11: BAPD255 | BQ11: STD | BR11: Standard | CG11: 45657 | CH11: P01 | CI11: 43679 | CJ11: PJF_TASKS | CK11: FINANCIAL
B12: OK | D12: CREATE | E12: BIL-1007990 | F12: TESTME-FR03319FR-BAPD25501-GUY Collège ECO-Q RM [3319_BAPD25501] | G12: TESTME-FR03319FR-BAPD25501-GUY Collège ECO-Q RM [3319_BAPD25501] | H12: DRAFT | I12: EGIS BATIMENTS ILE DE FRANCE | J12: =_xlfn.XLOOKUP(I12,LE!A:A,LE!F:F,,1) -> 0 | K12: SL-Buildings-CC-12-IDMI-01-Ile de France-BU-FR03305FR_EGIS BAT IDF | L12: SL-Buildings-CC-12-IDMI-01-Ile de France-BU-FR03305FR_EGIS BAT IDF | M12: EGIS BATIMENTS ILE DE FRANCE Billable E&SC Small Project | N12: EGIS BATIMENTS ILE DE FRANCE Billable E&SC Small Project | V12: EUR | X12: Corporate | Y12: T | Z12: FALSE | AA12: FALSE | AB12: TRUE | AC12: TRUE | AD12: ESQ APS PC APD Loi EAU | AE12: P02 | AG12: FINANCIAL | BN12: 46387 | BO12: 43679 | BP12: BAPD255 | BQ12: STD | BR12: Standard | CG12: 46162 | CH12: P02 | CI12: 43679 | CJ12: PJF_TASKS | CK12: FINANCIAL
B13: OK | D13: CREATE | E13: BIL-1007990 | F13: TESTME-FR03319FR-BAPD25501-GUY Collège ECO-Q RM [3319_BAPD25501] | G13: TESTME-FR03319FR-BAPD25501-GUY Collège ECO-Q RM [3319_BAPD25501] | H13: DRAFT | I13: EGIS BATIMENTS ILE DE FRANCE | J13: =_xlfn.XLOOKUP(I13,LE!A:A,LE!F:F,,1) -> 0 | K13: SL-Buildings-CC-12-IDMI-01-Ile de France-BU-FR03305FR_EGIS BAT IDF | L13: SL-Buildings-CC-12-IDMI-01-Ile de France-BU-FR03305FR_EGIS BAT IDF | M13: EGIS BATIMENTS ILE DE FRANCE Billable E&SC Small Project | N13: EGIS BATIMENTS ILE DE FRANCE Billable E&SC Small Project | V13: EUR | X13: Corporate | Y13: T | Z13: FALSE | AA13: FALSE | AB13: TRUE | AC13: TRUE | AD13: PRO | AE13: P03 | AG13: FINANCIAL | BN13: 46387 | BO13: 43679 | BP13: BAPD255 | BQ13: STD | BR13: Standard | CG13: 46162 | CH13: P03 | CI13: 43679 | CJ13: PJF_TASKS | CK13: FINANCIAL
B14: OK | D14: CREATE | E14: BIL-1007990 | F14: TESTME-FR03319FR-BAPD25501-GUY Collège ECO-Q RM [3319_BAPD25501] | G14: TESTME-FR03319FR-BAPD25501-GUY Collège ECO-Q RM [3319_BAPD25501] | H14: DRAFT | I14: EGIS BATIMENTS ILE DE FRANCE | J14: =_xlfn.XLOOKUP(I14,LE!A:A,LE!F:F,,1) -> 0 | K14: SL-Buildings-CC-12-IDMI-01-Ile de France-BU-FR03305FR_EGIS BAT IDF | L14: SL-Buildings-CC-12-IDMI-01-Ile de France-BU-FR03305FR_EGIS BAT IDF | M14: EGIS BATIMENTS ILE DE FRANCE Billable E&SC Small Project | N14: EGIS BATIMENTS ILE DE FRANCE Billable E&SC Small Project | V14: EUR | X14: Corporate | Y14: T | Z14: FALSE | AA14: FALSE | AB14: TRUE | AC14: TRUE | AD14: ACT | AE14: P04 | AG14: FINANCIAL | BN14: 46387 | BO14: 43679 | BP14: BAPD255 | BQ14: STD | BR14: Standard | CG14: 46162 | CH14: P04 | CI14: 43679 | CJ14: PJF_TASKS | CK14: FINANCIAL
B15: OK | D15: CREATE | E15: BIL-1007990 | F15: TESTME-FR03319FR-BAPD25501-GUY Collège ECO-Q RM [3319_BAPD25501] | G15: TESTME-FR03319FR-BAPD25501-GUY Collège ECO-Q RM [3319_BAPD25501] | H15: DRAFT | I15: EGIS BATIMENTS ILE DE FRANCE | J15: =_xlfn.XLOOKUP(I15,LE!A:A,LE!F:F,,1) -> 0 | K15: SL-Buildings-CC-12-IDMI-01-Ile de France-BU-FR03305FR_EGIS BAT IDF | L15: SL-Buildings-CC-12-IDMI-01-Ile de France-BU-FR03305FR_EGIS BAT IDF | M15: EGIS BATIMENTS ILE DE FRANCE Billable E&SC Small Project | N15: EGIS BATIMENTS ILE DE FRANCE Billable E&SC Small Project | V15: EUR | X15: Corporate | Y15: T | Z15: FALSE | AA15: FALSE | AB15: TRUE | AC15: TRUE | AD15: VISA DET AOR | AE15: P05 | AG15: FINANCIAL | BN15: 46387 | BO15: 43679 | BP15: BAPD255 | BQ15: STD | BR15: Standard | CG15: 46387 | CH15: P05 | CI15: 43679 | CJ15: PJF_TASKS | CK15: FINANCIAL
B16: OK | D16: CREATE | E16: BIL-1007990 | F16: TESTME-FR03319FR-BAPD25501-GUY Collège ECO-Q RM [3319_BAPD25501] | G16: TESTME-FR03319FR-BAPD25501-GUY Collège ECO-Q RM [3319_BAPD25501] | H16: DRAFT | I16: EGIS BATIMENTS ILE DE FRANCE | J16: =_xlfn.XLOOKUP(I16,LE!A:A,LE!F:F,,1) -> 0 | K16: SL-Buildings-CC-12-IDMI-01-Ile de France-BU-FR03305FR_EGIS BAT IDF | L16: SL-Buildings-CC-12-IDMI-01-Ile de France-BU-FR03305FR_EGIS BAT IDF | M16: EGIS BATIMENTS ILE DE FRANCE Billable E&SC Small Project | N16: EGIS BATIMENTS ILE DE FRANCE Billable E&SC Small Project | V16: EUR | X16: Corporate | Y16: T | Z16: FALSE | AA16: FALSE | AB16: TRUE | AC16: TRUE | AD16: Facturation Milestone Oracle 2025 | AE16: P97 | AG16: FINANCIAL | BN16: 46387 | BO16: 43679 | BP16: BAPD255 | BQ16: STD | BR16: Standard | CG16: 46162 | CH16: P97 | CI16: 43679 | CJ16: PJF_TASKS | CK16: FINANCIAL
B17: OK | D17: CREATE | E17: BIL-1007990 | F17: TESTME-FR03319FR-BAPD25501-GUY Collège ECO-Q RM [3319_BAPD25501] | G17: TESTME-FR03319FR-BAPD25501-GUY Collège ECO-Q RM [3319_BAPD25501] | H17: DRAFT | I17: EGIS BATIMENTS ILE DE FRANCE | J17: =_xlfn.XLOOKUP(I17,LE!A:A,LE!F:F,,1) -> 0 | K17: SL-Buildings-CC-12-IDMI-01-Ile de France-BU-FR03305FR_EGIS BAT IDF | L17: SL-Buildings-CC-12-IDMI-01-Ile de France-BU-FR03305FR_EGIS BAT IDF | M17: EGIS BATIMENTS ILE DE FRANCE Billable E&SC Small Project | N17: EGIS BATIMENTS ILE DE FRANCE Billable E&SC Small Project | V17: EUR | X17: Corporate | Y17: T | Z17: FALSE | AA17: FALSE | AB17: TRUE | AC17: TRUE | AV17: Project Classification | AW17: Client Project | BN17: 46387 | BO17: 43679 | BP17: BAPD255 | BQ17: STD | BR17: Standard
B18: OK | D18: CREATE | E18: BIL-1007990 | F18: TESTME-FR03319FR-BAPD25501-GUY Collège ECO-Q RM [3319_BAPD25501] | G18: TESTME-FR03319FR-BAPD25501-GUY Collège ECO-Q RM [3319_BAPD25501] | H18: DRAFT | I18: EGIS BATIMENTS ILE DE FRANCE | J18: =_xlfn.XLOOKUP(I18,LE!A:A,LE!F:F,,1) -> 0 | K18: SL-Buildings-CC-12-IDMI-01-Ile de France-BU-FR03305FR_EGIS BAT IDF | L18: SL-Buildings-CC-12-IDMI-01-Ile de France-BU-FR03305FR_EGIS BAT IDF | M18: EGIS BATIMENTS ILE DE FRANCE Billable E&SC Small Project | N18: EGIS BATIMENTS ILE DE FRANCE Billable E&SC Small Project | V18: EUR | X18: Corporate | Y18: T | Z18: FALSE | AA18: FALSE | AB18: TRUE | AC18: TRUE | AS18: Benoit.THERON@egis-group.com | AT18: Project Manager | AU18: 43679 | BN18: 46387 | BO18: 43679 | BP18: BAPD255 | BQ18: STD | BR18: Standard
B19: OK | D19: CREATE | E19: BIL-1007990 | F19: TESTME-FR03319FR-BAPD25501-GUY Collège ECO-Q RM [3319_BAPD25501] | G19: TESTME-FR03319FR-BAPD25501-GUY Collège ECO-Q RM [3319_BAPD25501] | H19: DRAFT | I19: EGIS BATIMENTS ILE DE FRANCE | J19: =_xlfn.XLOOKUP(I19,LE!A:A,LE!F:F,,1) -> 0 | K19: SL-Buildings-CC-12-IDMI-01-Ile de France-BU-FR03305FR_EGIS BAT IDF | L19: SL-Buildings-CC-12-IDMI-01-Ile de France-BU-FR03305FR_EGIS BAT IDF | M19: EGIS BATIMENTS ILE DE FRANCE Billable E&SC Small Project | N19: EGIS BATIMENTS ILE DE FRANCE Billable E&SC Small Project | V19: EUR | X19: Corporate | Y19: T | Z19: FALSE | AA19: FALSE | AB19: TRUE | AC19: TRUE | AS19: Rokhaya.NDIAYE@egis-group.com | AT19: Financial Controller | AU19: 43679 | BN19: 46387 | BO19: 43679 | BP19: BAPD255 | BQ19: STD | BR19: Standard
B20: OK | D20: CREATE | E20: BIL-1007990 | F20: TESTME-FR03319FR-BAPD25501-GUY Collège ECO-Q RM [3319_BAPD25501] | G20: TESTME-FR03319FR-BAPD25501-GUY Collège ECO-Q RM [3319_BAPD25501] | H20: DRAFT | I20: EGIS BATIMENTS ILE DE FRANCE | J20: =_xlfn.XLOOKUP(I20,LE!A:A,LE!F:F,,1) -> 0 | K20: SL-Buildings-CC-12-IDMI-01-Ile de France-BU-FR03305FR_EGIS BAT IDF | L20: SL-Buildings-CC-12-IDMI-01-Ile de France-BU-FR03305FR_EGIS BAT IDF | M20: EGIS BATIMENTS ILE DE FRANCE Billable E&SC Small Project | N20: EGIS BATIMENTS ILE DE FRANCE Billable E&SC Small Project | V20: EUR | X20: Corporate | Y20: T | Z20: FALSE | AA20: FALSE | AB20: TRUE | AC20: TRUE | AS20: Sebastien.PLICHON@egis-group.com | AT20: RBLD | AU20: 43679 | BN20: 46387 | BO20: 43679 | BP20: BAPD255 | BQ20: STD | BR20: Standard
B21: OK | D21: CREATE | E21: BIL-1007990 | F21: TESTME-FR03319FR-BAPD25501-GUY Collège ECO-Q RM [3319_BAPD25501] | G21: TESTME-FR03319FR-BAPD25501-GUY Collège ECO-Q RM [3319_BAPD25501] | H21: DRAFT | I21: EGIS BATIMENTS ILE DE FRANCE | J21: =_xlfn.XLOOKUP(I21,LE!A:A,LE!F:F,,1) -> 0 | K21: SL-Buildings-CC-12-IDMI-01-Ile de France-BU-FR03305FR_EGIS BAT IDF | L21: SL-Buildings-CC-12-IDMI-01-Ile de France-BU-FR03305FR_EGIS BAT IDF | M21: EGIS BATIMENTS ILE DE FRANCE Billable E&SC Small Project | N21: EGIS BATIMENTS ILE DE FRANCE Billable E&SC Small Project | V21: EUR | X21: Corporate | Y21: T | Z21: FALSE | AA21: FALSE | AB21: TRUE | AC21: TRUE | AS21: Cedric.ARNAUD@egis-group.com | AT21: Project Sponsor / RBLD Delegate | AU21: 45658 | BN21: 46387 | BO21: 43679 | BP21: BAPD255 | BQ21: STD | BR21: Standard
B22: OK | D22: CREATE | E22: BIL-1007990 | F22: TESTME-FR03319FR-BAPD25501-GUY Collège ECO-Q RM [3319_BAPD25501] | G22: TESTME-FR03319FR-BAPD25501-GUY Collège ECO-Q RM [3319_BAPD25501] | H22: DRAFT | I22: EGIS BATIMENTS ILE DE FRANCE | J22: =_xlfn.XLOOKUP(I22,LE!A:A,LE!F:F,,1) -> 0 | K22: SL-Buildings-CC-12-IDMI-01-Ile de France-BU-FR03305FR_EGIS BAT IDF | L22: SL-Buildings-CC-12-IDMI-01-Ile de France-BU-FR03305FR_EGIS BAT IDF | M22: EGIS BATIMENTS ILE DE FRANCE Billable E&SC Small Project | N22: EGIS BATIMENTS ILE DE FRANCE Billable E&SC Small Project | V22: EUR | X22: Corporate | Y22: T | Z22: FALSE | AA22: FALSE | AB22: TRUE | AC22: TRUE | AS22: Cedric.ARNAUD@egis-group.com | AT22: Project Manager | AU22: 45658 | BN22: 46387 | BO22: 43679 | BP22: BAPD255 | BQ22: STD | BR22: Standard
B23: OK | D23: CREATE | E23: BIL-1007991 | F23: TESTME--TESTME-FR03319FR-BAPD25501-GUY Collège ECO-Q RM [3319_BAPD25501] | G23: TESTME--TESTME-FR03319FR-BAPD25501-GUY Collège ECO-Q RM [3319_BAPD25501] | H23: DRAFT | I23: EGIS BATIMENTS ILE DE FRANCE | J23: =_xlfn.XLOOKUP(I23,LE!A:A,LE!F:F,,1) -> 0 | K23: SL-Buildings-CC-12-IDMI-01-Ile de France-BU-FR03305FR_EGIS BAT IDF | L23: SL-Buildings-CC-12-IDMI-01-Ile de France-BU-FR03305FR_EGIS BAT IDF | M23: EGIS BATIMENTS ILE DE FRANCE Billable E&SC Small Project | N23: EGIS BATIMENTS ILE DE FRANCE Billable E&SC Small Project | V23: EUR | X23: Corporate | Y23: T | Z23: FALSE | AA23: FALSE | AB23: TRUE | AC23: TRUE | AD23: O - Offre | AE23: P01 | AG23: FINANCIAL | BN23: 47087 | BO23: 43644 | BP23: AVPC038 | BQ23: STD | BR23: Standard | CG23: 45657 | CH23: P01 | CI23: 43644 | CJ23: PJF_TASKS | CK23: FINANCIAL
B24: OK | D24: CREATE | E24: BIL-1007991 | F24: TESTME--TESTME-FR03319FR-BAPD25501-GUY Collège ECO-Q RM [3319_BAPD25501] | G24: TESTME--TESTME-FR03319FR-BAPD25501-GUY Collège ECO-Q RM [3319_BAPD25501] | H24: DRAFT | I24: EGIS BATIMENTS ILE DE FRANCE | J24: =_xlfn.XLOOKUP(I24,LE!A:A,LE!F:F,,1) -> 0 | K24: SL-Buildings-CC-12-IDMI-01-Ile de France-BU-FR03305FR_EGIS BAT IDF | L24: SL-Buildings-CC-12-IDMI-01-Ile de France-BU-FR03305FR_EGIS BAT IDF | M24: EGIS BATIMENTS ILE DE FRANCE Billable E&SC Small Project | N24: EGIS BATIMENTS ILE DE FRANCE Billable E&SC Small Project | V24: EUR | X24: Corporate | Y24: T | Z24: FALSE | AA24: FALSE | AB24: TRUE | AC24: TRUE | AD24: E - Etudes | AE24: P02 | AG24: FINANCIAL | BN24: 47087 | BO24: 43644 | BP24: AVPC038 | BQ24: STD | BR24: Standard | CG24: 47087 | CH24: P02 | CI24: 43644 | CJ24: PJF_TASKS | CK24: FINANCIAL
B25: OK | D25: CREATE | E25: BIL-1007991 | F25: TESTME--TESTME-FR03319FR-BAPD25501-GUY Collège ECO-Q RM [3319_BAPD25501] | G25: TESTME--TESTME-FR03319FR-BAPD25501-GUY Collège ECO-Q RM [3319_BAPD25501] | H25: DRAFT | I25: EGIS BATIMENTS ILE DE FRANCE | J25: =_xlfn.XLOOKUP(I25,LE!A:A,LE!F:F,,1) -> 0 | K25: SL-Buildings-CC-12-IDMI-01-Ile de France-BU-FR03305FR_EGIS BAT IDF | L25: SL-Buildings-CC-12-IDMI-01-Ile de France-BU-FR03305FR_EGIS BAT IDF | M25: EGIS BATIMENTS ILE DE FRANCE Billable E&SC Small Project | N25: EGIS BATIMENTS ILE DE FRANCE Billable E&SC Small Project | V25: EUR | X25: Corporate | Y25: T | Z25: FALSE | AA25: FALSE | AB25: TRUE | AC25: TRUE | AD25: P03 - Phase 03 | AE25: P03 | AG25: FINANCIAL | BN25: 47087 | BO25: 43644 | BP25: AVPC038 | BQ25: STD | BR25: Standard | CG25: 47087 | CH25: P03 | CI25: 43644 | CJ25: PJF_TASKS | CK25: FINANCIAL
B26: OK | D26: CREATE | E26: BIL-1007991 | F26: TESTME--TESTME-FR03319FR-BAPD25501-GUY Collège ECO-Q RM [3319_BAPD25501] | G26: TESTME--TESTME-FR03319FR-BAPD25501-GUY Collège ECO-Q RM [3319_BAPD25501] | H26: DRAFT | I26: EGIS BATIMENTS ILE DE FRANCE | J26: =_xlfn.XLOOKUP(I26,LE!A:A,LE!F:F,,1) -> 0 | K26: SL-Buildings-CC-12-IDMI-01-Ile de France-BU-FR03305FR_EGIS BAT IDF | L26: SL-Buildings-CC-12-IDMI-01-Ile de France-BU-FR03305FR_EGIS BAT IDF | M26: EGIS BATIMENTS ILE DE FRANCE Billable E&SC Small Project | N26: EGIS BATIMENTS ILE DE FRANCE Billable E&SC Small Project | V26: EUR | X26: Corporate | Y26: T | Z26: FALSE | AA26: FALSE | AB26: TRUE | AC26: TRUE | AD26: Facturation Milestone Oracle 2025 | AE26: P97 | AG26: FINANCIAL | BN26: 47087 | BO26: 43644 | BP26: AVPC038 | BQ26: STD | BR26: Standard | CG26: 47087 | CH26: P97 | CI26: 43644 | CJ26: PJF_TASKS | CK26: FINANCIAL
B27: OK | D27: CREATE | E27: BIL-1007991 | F27: TESTME--TESTME-FR03319FR-BAPD25501-GUY Collège ECO-Q RM [3319_BAPD25501] | G27: TESTME--TESTME-FR03319FR-BAPD25501-GUY Collège ECO-Q RM [3319_BAPD25501] | H27: DRAFT | I27: EGIS BATIMENTS ILE DE FRANCE | J27: =_xlfn.XLOOKUP(I27,LE!A:A,LE!F:F,,1) -> 0 | K27: SL-Buildings-CC-12-IDMI-01-Ile de France-BU-FR03305FR_EGIS BAT IDF | L27: SL-Buildings-CC-12-IDMI-01-Ile de France-BU-FR03305FR_EGIS BAT IDF | M27: EGIS BATIMENTS ILE DE FRANCE Billable E&SC Small Project | N27: EGIS BATIMENTS ILE DE FRANCE Billable E&SC Small Project | V27: EUR | X27: Corporate | Y27: T | Z27: FALSE | AA27: FALSE | AB27: TRUE | AC27: TRUE | AV27: Project Classification | AW27: Client Project | BN27: 47087 | BO27: 43644 | BP27: AVPC038 | BQ27: STD | BR27: Standard
B28: OK | D28: CREATE | E28: BIL-1007991 | F28: TESTME--TESTME-FR03319FR-BAPD25501-GUY Collège ECO-Q RM [3319_BAPD25501] | G28: TESTME--TESTME-FR03319FR-BAPD25501-GUY Collège ECO-Q RM [3319_BAPD25501] | H28: DRAFT | I28: EGIS BATIMENTS ILE DE FRANCE | J28: =_xlfn.XLOOKUP(I28,LE!A:A,LE!F:F,,1) -> 0 | K28: SL-Buildings-CC-12-IDMI-01-Ile de France-BU-FR03305FR_EGIS BAT IDF | L28: SL-Buildings-CC-12-IDMI-01-Ile de France-BU-FR03305FR_EGIS BAT IDF | M28: EGIS BATIMENTS ILE DE FRANCE Billable E&SC Small Project | N28: EGIS BATIMENTS ILE DE FRANCE Billable E&SC Small Project | V28: EUR | X28: Corporate | Y28: T | Z28: FALSE | AA28: FALSE | AB28: TRUE | AC28: TRUE | AS28: Romain.PENNES@egis-group.com | AT28: Project Manager | AU28: 44749 | BN28: 47087 | BO28: 43644 | BP28: AVPC038 | BQ28: STD | BR28: Standard
B29: OK | D29: CREATE | E29: BIL-1007991 | F29: TESTME--TESTME-FR03319FR-BAPD25501-GUY Collège ECO-Q RM [3319_BAPD25501] | G29: TESTME--TESTME-FR03319FR-BAPD25501-GUY Collège ECO-Q RM [3319_BAPD25501] | H29: DRAFT | I29: EGIS BATIMENTS ILE DE FRANCE | J29: =_xlfn.XLOOKUP(I29,LE!A:A,LE!F:F,,1) -> 0 | K29: SL-Buildings-CC-12-IDMI-01-Ile de France-BU-FR03305FR_EGIS BAT IDF | L29: SL-Buildings-CC-12-IDMI-01-Ile de France-BU-FR03305FR_EGIS BAT IDF | M29: EGIS BATIMENTS ILE DE FRANCE Billable E&SC Small Project | N29: EGIS BATIMENTS ILE DE FRANCE Billable E&SC Small Project | V29: EUR | X29: Corporate | Y29: T | Z29: FALSE | AA29: FALSE | AB29: TRUE | AC29: TRUE | AS29: Rokhaya.NDIAYE@egis-group.com | AT29: Financial Controller | AU29: 43644 | BN29: 47087 | BO29: 43644 | BP29: AVPC038 | BQ29: STD | BR29: Standard
B30: OK | D30: CREATE | E30: BIL-1007991 | F30: TESTME--TESTME-FR03319FR-BAPD25501-GUY Collège ECO-Q RM [3319_BAPD25501] | G30: TESTME--TESTME-FR03319FR-BAPD25501-GUY Collège ECO-Q RM [3319_BAPD25501] | H30: DRAFT | I30: EGIS BATIMENTS ILE DE FRANCE | J30: =_xlfn.XLOOKUP(I30,LE!A:A,LE!F:F,,1) -> 0 | K30: SL-Buildings-CC-12-IDMI-01-Ile de France-BU-FR03305FR_EGIS BAT IDF | L30: SL-Buildings-CC-12-IDMI-01-Ile de France-BU-FR03305FR_EGIS BAT IDF | M30: EGIS BATIMENTS ILE DE FRANCE Billable E&SC Small Project | N30: EGIS BATIMENTS ILE DE FRANCE Billable E&SC Small Project | V30: EUR | X30: Corporate | Y30: T | Z30: FALSE | AA30: FALSE | AB30: TRUE | AC30: TRUE | AS30: Cedric.ARNAUD@egis-group.com | AT30: Project Sponsor / RBLD Delegate | AU30: 45352 | BN30: 47087 | BO30: 43644 | BP30: AVPC038 | BQ30: STD | BR30: Standard
B31: OK | D31: CREATE | E31: BIL-1007991 | F31: TESTME--TESTME-FR03319FR-BAPD25501-GUY Collège ECO-Q RM [3319_BAPD25501] | G31: TESTME--TESTME-FR03319FR-BAPD25501-GUY Collège ECO-Q RM [3319_BAPD25501] | H31: DRAFT | I31: EGIS BATIMENTS ILE DE FRANCE | J31: =_xlfn.XLOOKUP(I31,LE!A:A,LE!F:F,,1) -> 0 | K31: SL-Buildings-CC-12-IDMI-01-Ile de France-BU-FR03305FR_EGIS BAT IDF | L31: SL-Buildings-CC-12-IDMI-01-Ile de France-BU-FR03305FR_EGIS BAT IDF | M31: EGIS BATIMENTS ILE DE FRANCE Billable E&SC Small Project | N31: EGIS BATIMENTS ILE DE FRANCE Billable E&SC Small Project | V31: EUR | X31: Corporate | Y31: T | Z31: FALSE | AA31: FALSE | AB31: TRUE | AC31: TRUE | AS31: Sebastien.PLICHON@egis-group.com | AT31: RBLD | AU31: 43644 | BN31: 47087 | BO31: 43644 | BP31: AVPC038 | BQ31: STD | BR31: Standard
B32: OK | D32: CREATE | E32: BIL-1007991 | F32: TESTME--TESTME-FR03319FR-BAPD25501-GUY Collège ECO-Q RM [3319_BAPD25501] | G32: TESTME--TESTME-FR03319FR-BAPD25501-GUY Collège ECO-Q RM [3319_BAPD25501] | H32: DRAFT | I32: EGIS BATIMENTS ILE DE FRANCE | J32: =_xlfn.XLOOKUP(I32,LE!A:A,LE!F:F,,1) -> 0 | K32: SL-Buildings-CC-12-IDMI-01-Ile de France-BU-FR03305FR_EGIS BAT IDF | L32: SL-Buildings-CC-12-IDMI-01-Ile de France-BU-FR03305FR_EGIS BAT IDF | M32: EGIS BATIMENTS ILE DE FRANCE Billable E&SC Small Project | N32: EGIS BATIMENTS ILE DE FRANCE Billable E&SC Small Project | V32: EUR | X32: Corporate | Y32: T | Z32: FALSE | AA32: FALSE | AB32: TRUE | AC32: TRUE | AS32: Cedric.ARNAUD@egis-group.com | AT32: Project Manager | AU32: 45658 | BN32: 47087 | BO32: 43644 | BP32: AVPC038 | BQ32: STD | BR32: Standard
B33: OK | D33: CREATE | E33: BIL-1007992 | F33: TESTME-FR03319FR-AVPC03801-GUAD> SSI Ext T1 P Caraïbes [3319_AVPC03801] | G33: TESTME-FR03319FR-AVPC03801-GUAD> SSI Ext T1 P Caraïbes [3319_AVPC03801] | H33: DRAFT | I33: EGIS BATIMENTS ILE DE FRANCE | J33: EGIS BATIMENTS ILE DE FRANCE | K33: SL-Buildings-CC-12-IDMI-01-Ile de France-BU-FR03305FR_EGIS BAT IDF | L33: SL-Buildings-CC-12-IDMI-01-Ile de France-BU-FR03305FR_EGIS BAT IDF | M33: EGIS BATIMENTS ILE DE FRANCE Billable E&SC Small Project | N33: EGIS BATIMENTS ILE DE FRANCE Billable E&SC Small Project | V33: EUR | X33: Corporate | Y33: T | Z33: FALSE | AA33: FALSE | AB33: TRUE | AC33: TRUE | AD33: O - Offre | AE33: P01 | AG33: FINANCIAL | BN33: 47087 | BO33: 43644 | BP33: AVPC038 | BQ33: STD | BR33: Standard | CG33: 45657 | CH33: P01 | CI33: 43644 | CJ33: PJF_TASKS | CK33: FINANCIAL
B34: OK | D34: CREATE | E34: BIL-1007992 | F34: TESTME-FR03319FR-AVPC03801-GUAD> SSI Ext T1 P Caraïbes [3319_AVPC03801] | G34: TESTME-FR03319FR-AVPC03801-GUAD> SSI Ext T1 P Caraïbes [3319_AVPC03801] | H34: DRAFT | I34: EGIS BATIMENTS ILE DE FRANCE | J34: EGIS BATIMENTS ILE DE FRANCE | K34: SL-Buildings-CC-12-IDMI-01-Ile de France-BU-FR03305FR_EGIS BAT IDF | L34: SL-Buildings-CC-12-IDMI-01-Ile de France-BU-FR03305FR_EGIS BAT IDF | M34: EGIS BATIMENTS ILE DE FRANCE Billable E&SC Small Project | N34: EGIS BATIMENTS ILE DE FRANCE Billable E&SC Small Project | V34: EUR | X34: Corporate | Y34: T | Z34: FALSE | AA34: FALSE | AB34: TRUE | AC34: TRUE | AD34: E - Etudes | AE34: P02 | AG34: FINANCIAL | BN34: 47087 | BO34: 43644 | BP34: AVPC038 | BQ34: STD | BR34: Standard | CG34: 47087 | CH34: P02 | CI34: 43644 | CJ34: PJF_TASKS | CK34: FINANCIAL
B35: OK | D35: CREATE | E35: BIL-1007992 | F35: TESTME-FR03319FR-AVPC03801-GUAD> SSI Ext T1 P Caraïbes [3319_AVPC03801] | G35: TESTME-FR03319FR-AVPC03801-GUAD> SSI Ext T1 P Caraïbes [3319_AVPC03801] | H35: DRAFT | I35: EGIS BATIMENTS ILE DE FRANCE | J35: EGIS BATIMENTS ILE DE FRANCE | K35: SL-Buildings-CC-12-IDMI-01-Ile de France-BU-FR03305FR_EGIS BAT IDF | L35: SL-Buildings-CC-12-IDMI-01-Ile de France-BU-FR03305FR_EGIS BAT IDF | M35: EGIS BATIMENTS ILE DE FRANCE Billable E&SC Small Project | N35: EGIS BATIMENTS ILE DE FRANCE Billable E&SC Small Project | V35: EUR | X35: Corporate | Y35: T | Z35: FALSE | AA35: FALSE | AB35: TRUE | AC35: TRUE | AD35: P03 - Phase 03 | AE35: P03 | AG35: FINANCIAL | BN35: 47087 | BO35: 43644 | BP35: AVPC038 | BQ35: STD | BR35: Standard | CG35: 47087 | CH35: P03 | CI35: 43644 | CJ35: PJF_TASKS | CK35: FINANCIAL
B36: OK | D36: CREATE | E36: BIL-1007992 | F36: TESTME-FR03319FR-AVPC03801-GUAD> SSI Ext T1 P Caraïbes [3319_AVPC03801] | G36: TESTME-FR03319FR-AVPC03801-GUAD> SSI Ext T1 P Caraïbes [3319_AVPC03801] | H36: DRAFT | I36: EGIS BATIMENTS ILE DE FRANCE | J36: EGIS BATIMENTS ILE DE FRANCE | K36: SL-Buildings-CC-12-IDMI-01-Ile de France-BU-FR03305FR_EGIS BAT IDF | L36: SL-Buildings-CC-12-IDMI-01-Ile de France-BU-FR03305FR_EGIS BAT IDF | M36: EGIS BATIMENTS ILE DE FRANCE Billable E&SC Small Project | N36: EGIS BATIMENTS ILE DE FRANCE Billable E&SC Small Project | V36: EUR | X36: Corporate | Y36: T | Z36: FALSE | AA36: FALSE | AB36: TRUE | AC36: TRUE | AD36: Facturation Milestone Oracle 2025 | AE36: P97 | AG36: FINANCIAL | BN36: 47087 | BO36: 43644 | BP36: AVPC038 | BQ36: STD | BR36: Standard | CG36: 47087 | CH36: P97 | CI36: 43644 | CJ36: PJF_TASKS | CK36: FINANCIAL
B37: OK | D37: CREATE | E37: BIL-1007992 | F37: TESTME-FR03319FR-AVPC03801-GUAD> SSI Ext T1 P Caraïbes [3319_AVPC03801] | G37: TESTME-FR03319FR-AVPC03801-GUAD> SSI Ext T1 P Caraïbes [3319_AVPC03801] | H37: DRAFT | I37: EGIS BATIMENTS ILE DE FRANCE | J37: EGIS BATIMENTS ILE DE FRANCE | K37: SL-Buildings-CC-12-IDMI-01-Ile de France-BU-FR03305FR_EGIS BAT IDF | L37: SL-Buildings-CC-12-IDMI-01-Ile de France-BU-FR03305FR_EGIS BAT IDF | M37: EGIS BATIMENTS ILE DE FRANCE Billable E&SC Small Project | N37: EGIS BATIMENTS ILE DE FRANCE Billable E&SC Small Project | V37: EUR | X37: Corporate | Y37: T | Z37: FALSE | AA37: FALSE | AB37: TRUE | AC37: TRUE | AV37: Project Classification | AW37: Client Project | BN37: 47087 | BO37: 43644 | BP37: AVPC038 | BQ37: STD | BR37: Standard
B38: OK | D38: CREATE | E38: BIL-1007992 | F38: TESTME-FR03319FR-AVPC03801-GUAD> SSI Ext T1 P Caraïbes [3319_AVPC03801] | G38: TESTME-FR03319FR-AVPC03801-GUAD> SSI Ext T1 P Caraïbes [3319_AVPC03801] | H38: DRAFT | I38: EGIS BATIMENTS ILE DE FRANCE | J38: EGIS BATIMENTS ILE DE FRANCE | K38: SL-Buildings-CC-12-IDMI-01-Ile de France-BU-FR03305FR_EGIS BAT IDF | L38: SL-Buildings-CC-12-IDMI-01-Ile de France-BU-FR03305FR_EGIS BAT IDF | M38: EGIS BATIMENTS ILE DE FRANCE Billable E&SC Small Project | N38: EGIS BATIMENTS ILE DE FRANCE Billable E&SC Small Project | V38: EUR | X38: Corporate | Y38: T | Z38: FALSE | AA38: FALSE | AB38: TRUE | AC38: TRUE | AS38: Romain.PENNES@egis-group.com | AT38: Project Manager | AU38: 44749 | BN38: 47087 | BO38: 43644 | BP38: AVPC038 | BQ38: STD | BR38: Standard
B39: OK | D39: CREATE | E39: BIL-1007992 | F39: TESTME-FR03319FR-AVPC03801-GUAD> SSI Ext T1 P Caraïbes [3319_AVPC03801] | G39: TESTME-FR03319FR-AVPC03801-GUAD> SSI Ext T1 P Caraïbes [3319_AVPC03801] | H39: DRAFT | I39: EGIS BATIMENTS ILE DE FRANCE | J39: EGIS BATIMENTS ILE DE FRANCE | K39: SL-Buildings-CC-12-IDMI-01-Ile de France-BU-FR03305FR_EGIS BAT IDF | L39: SL-Buildings-CC-12-IDMI-01-Ile de France-BU-FR03305FR_EGIS BAT IDF | M39: EGIS BATIMENTS ILE DE FRANCE Billable E&SC Small Project | N39: EGIS BATIMENTS ILE DE FRANCE Billable E&SC Small Project | V39: EUR | X39: Corporate | Y39: T | Z39: FALSE | AA39: FALSE | AB39: TRUE | AC39: TRUE | AS39: Rokhaya.NDIAYE@egis-group.com | AT39: Financial Controller | AU39: 43644 | BN39: 47087 | BO39: 43644 | BP39: AVPC038 | BQ39: STD | BR39: Standard
B40: OK | D40: CREATE | E40: BIL-1007992 | F40: TESTME-FR03319FR-AVPC03801-GUAD> SSI Ext T1 P Caraïbes [3319_AVPC03801] | G40: TESTME-FR03319FR-AVPC03801-GUAD> SSI Ext T1 P Caraïbes [3319_AVPC03801] | H40: DRAFT | I40: EGIS BATIMENTS ILE DE FRANCE | J40: EGIS BATIMENTS ILE DE FRANCE | K40: SL-Buildings-CC-12-IDMI-01-Ile de France-BU-FR03305FR_EGIS BAT IDF | L40: SL-Buildings-CC-12-IDMI-01-Ile de France-BU-FR03305FR_EGIS BAT IDF | M40: EGIS BATIMENTS ILE DE FRANCE Billable E&SC Small Project | N40: EGIS BATIMENTS ILE DE FRANCE Billable E&SC Small Project | V40: EUR | X40: Corporate | Y40: T | Z40: FALSE | AA40: FALSE | AB40: TRUE | AC40: TRUE | AS40: Cedric.ARNAUD@egis-group.com | AT40: Project Sponsor / RBLD Delegate | AU40: 45352 | BN40: 47087 | BO40: 43644 | BP40: AVPC038 | BQ40: STD | BR40: Standard
...

Sheet Templateold
A1: Columns | B1: Status | C1: Error Message | D1: Action | E1: ProjectNumber | F1: ProjectName | H1: ProjectStatusCode | I1: LegalEntityName | K1: OwningOrganizationName | M1: SourceTemplateName | O1: AllowCapitalizedInterestFlag | P1: AssetAllocationMethodCode | Q1: BurdenScheduleName | R1: BurdenScheduleFixedDate | S1: CapitalEventProcessingMethodCode | T1: CIntRateSchName | U1: CIntStopDate | V1: ProjectCurrencyCode | W1: CurrencyConvDate | X1: CurrencyConvRateType | Y1: CurrencyConvDateTypeCode | Z1: IncludeNotesInKPINotificationsFlag | AA1: KPINotificationEnabledFlag | AB1: PlanningProjectFlag | AC1: AllowCrossChargeFlag | AD1: TaskName | AE1: ExternalTaskId | AF1: ExternalParentTaskId | AG1: ElementType | AH1: ExpenseResourceName | AI1: LaborResourceName | AJ1: LaborResourceEmail | AK1: LaborPrimaryResource | AL1: RuleNumber | AM1: Billable | AN1: Chargeable | AO1: ExternalPredecessorTaskId | AP1: ExternalTaskId | AQ1: Lag | AR1: DependencyType | AS1: PersonEmail | AT1: ProjectRole | AU1: StartDate | AV1: ClassCategory | AW1: ClassCode | AX1: CodePercentage | AY1: OpportunityNumber | AZ1: OpportunityName | BA1: OpportunityAmount | BB1: OpportunityCustomerName | BC1: OpportunityCustomerNumber | BD1: OpportunityStatus | BE1: OpportunityWinConfPercent | BF1: PartyName | BG1: PartyNumber | BH1: BusinessUnitName | BI1: CategoryName | BJ1: DatatypeCode | BK1: FileContents | BL1: Title | BM1: FileName | BN1: ProjectEndDate | BO1: ProjectStartDate | BP1: crmNumber | BQ1: supplierPaymentProcess | BR1: supplierPaymentProcess_Display | BS1: domain | BT1: marketSegment | BU1: domain_Display | BV1: marketSegment_Display | BW1: specificities | BX1: specificities_Display | BY1: fundingSource | BZ1: fundingSource_Display | CA1: subFundingSource | CB1: subFundingSource_Display | CC1: procedures | CD1: procedures_Display | CE1: countryDestinationView | CF1: stateOrProvince | CG1: TaskFinishDate | CH1: TaskNumber | CI1: TaskStartDate | CJ1: ObjectType | CK1: ElementType
A2: Status | B2: Technical | C2: Technical | D2: Action | E2: Header | F2: Header | H2: Header | I2: Header | K2: Header | M2: Header | O2: Header | P2: Header | Q2: Header | R2: Header | S2: Header | T2: Header | U2: Header | V2: Header | W2: Header | X2: Header | Y2: Header | Z2: Header | AA2: Header | AB2: Header | AC2: Header | AD2: Tasks | AE2: Tasks | AF2: Tasks | AG2: Tasks | AH2: ExpenseResourceAssignments | AI2: LaborResourceAssignments | AJ2: LaborResourceAssignments | AK2: LaborResourceAssignments | AL2: TaskTransactionControls | AM2: TaskTransactionControls | AN2: TaskTransactionControls | AO2: TaskDependencies | AP2: TaskDependencies | AQ2: TaskDependencies | AR2: TaskDependencies | AS2: ProjectTeamMembers | AT2: ProjectTeamMembers | AU2: ProjectTeamMembers | AV2: ProjectClassifications | AW2: ProjectClassifications | AX2: ProjectClassifications | AY2: ProjectOpportunities | AZ2: ProjectOpportunities | BA2: ProjectOpportunities | BB2: ProjectOpportunities | BC2: ProjectOpportunities | BD2: ProjectOpportunities | BE2: ProjectOpportunities | BF2: ProjectCustomers | BG2: ProjectCustomers | BH2: ProviderBusinessUnits | BI2: Attachments | BJ2: Attachments | BK2: Attachments | BL2: Attachments | BM2: Attachments | BN2: Header | BO2: Header | BP2: Header | BQ2: Header | BR2: Header | BS2: Header | BT2: Header | BU2: Header | BV2: Header | BW2: Header | BX2: Header | BY2: Header | BZ2: Header | CA2: Header | CB2: Header | CC2: Header | CD2: Header | CE2: Header | CF2: Header | CG2: Tasks | CH2: Tasks | CI2: Tasks | CJ2: Tasks | CK2: Tasks
A3: Type | B3: Standard | C3: Standard | D3: Standard | E3: Standard | F3: Standard | H3: Standard | I3: Standard | K3: Standard | M3: Standard | O3: Standard | P3: Standard | Q3: Standard | R3: Standard | S3: Standard | T3: Standard | U3: Standard | V3: Standard | W3: Standard | X3: Standard | Y3: Standard | Z3: Standard | AA3: Standard | AB3: Standard | AC3: Standard | AD3: Standard | AE3: Standard | AF3: Standard | AG3: Standard | AH3: Standard | AI3: Standard | AJ3: Standard | AK3: Standard | AL3: Standard | AM3: Standard | AN3: Standard | AO3: Standard | AP3: Standard | AQ3: Standard | AR3: Standard | AS3: Standard | AT3: Standard | AU3: Standard | AV3: Standard | AW3: Standard | AX3: Standard | AY3: Standard | AZ3: Standard | BA3: Standard | BB3: Standard | BC3: Standard | BD3: Standard | BE3: Standard | BF3: Standard | BG3: Standard | BH3: Standard | BI3: Standard | BJ3: Standard | BK3: Standard | BL3: Standard | BM3: Standard | BN3: Standard | BO3: Standard | BP3: ProjectDFF | BQ3: ProjectDFF | BR3: ProjectDFF | BS3: ProjectDFF | BT3: ProjectDFF | BU3: ProjectDFF | BV3: ProjectDFF | BW3: ProjectDFF | BX3: ProjectDFF | BY3: ProjectDFF | BZ3: ProjectDFF | CA3: ProjectDFF | CB3: ProjectDFF | CC3: ProjectDFF | CD3: ProjectDFF | CE3: ProjectDFF | CF3: ProjectDFF | CG3: Standard | CH3: Standard | CI3: Standard | CJ3: TasksDFF | CK3: TasksDFF
A4: Custom Labels | B4: Status | C4: Error Message | D4: Action | E4: Project Number | F4: Project Name | G4: ProjectName to migrate | H4: Project Status Code | I4: Legal Entity Name | J4: Legal Entity Name to migrate | K4: Owning Organization Name | L4: Owning Organization Name to migrate | M4: Source Template Name | N4: SourceTemplateName to migrate | O4: Allow Capitalized Interest Flag | P4: Asset Allocation Method Code | Q4: Burden Schedule Name | R4: Burden Schedule Fixed Date | S4: Capital Event Processing Method Code | T4: CIntRateSchName | U4: CIntStopDate | V4: Project Currency Code | W4: Currency Conv Date | X4: Currency Conv Rate Type | Y4: Currency Conv Date Type Code | Z4: Include Notes In KPI Notifications Flag | AA4: KPI Notification Enabled Flag | AB4: Planning Project lag | AC4: Allow cross-charge transactions from other business units | AD4: Task Name | AE4: External Task Id | AF4: External Parent Task Id | AG4: Element Type | AH4: Expense Resource Name | AI4: Labor Resource Name | AJ4: Labor Resource Email | AK4: Labor Primary Resource | AL4: Rule Number | AM4: Billable | AN4: Chargeable | AO4: External Predecessor Task Id | AP4: External Task Id | AQ4: Lag | AR4: Dependency Type | AS4: Person Email | AT4: Project Role | AU4: Start Date | AV4: Class Category | AW4: Class Code | AX4: Code Percentage | AY4: Opportunity Number | AZ4: Opportunity Name | BA4: Opportunity Amount | BB4: Opportunity Customer Name | BC4: Opportunity Customer Number | BD4: Opportunity Status | BE4: Opportunity Win Conf Percent | BF4: Party Name | BG4: Party Number | BH4: BusinessUnitName | BI4: Category Name | BJ4: Data type Code | BK4: File Contents | BL4: Title | BM4: File Name | BN4: Project Finish Date | BO4: Project Start Date | CG4: Task Finish Date | CH4: Task Number | CI4: Task Start Date
B5: OK | D5: CREATE | E5: BIL-1007342 | F5: TESTUK1 | G5: ETS-BIL-1007342-TESTUK1 | H5: DRAFT | I5: EGIS UK - CONSULTING AND ENGINEERING LIMITED | J5: =_xlfn.XLOOKUP(I5,LE!A:A,LE!F:F,,1) -> 0 | K5: SL-Nuclear SL-CC-12-NTAI-21-Nuclear Technical Assistance-BU-GB03958GB_EGIS UK | L5: =_xlfn.XLOOKUP(K5,'ORG name (PPM)'!A:A,'ORG name (PPM)'!G:G,,1) -> 0 | M5: EGIS UK - CONSULTING AND ENGINEERING LIMITED Billable | N5: =_xlfn.XLOOKUP(M5,'source template'!A:A,'source template'!I:I,,1) -> 0 | V5: GBP | X5: Corporate | Y5: T | Z5: FALSE | AA5: FALSE | AB5: TRUE | AD5: Tender Costs | AE5: P01 | AG5: FINANCIAL | BN5: 47848 | BO5: 44927 | BP5: ZZZZZ | BQ5: STD | BR5: Standard | CG5: 47848 | CH5: P01 | CI5: 44927 | CJ5: PJF_TASKS | CK5: FINANCIAL
B6: OK | D6: CREATE | E6: BIL-1007342 | F6: TESTUK1 | G6: ETS-BIL-1007342-TESTUK1 | H6: DRAFT | I6: EGIS UK - CONSULTING AND ENGINEERING LIMITED | J6: =_xlfn.XLOOKUP(I6,LE!A:A,LE!F:F,,1) -> 0 | K6: SL-Nuclear SL-CC-12-NTAI-21-Nuclear Technical Assistance-BU-GB03958GB_EGIS UK | L6: =_xlfn.XLOOKUP(K6,'ORG name (PPM)'!A:A,'ORG name (PPM)'!G:G,,1) -> 0 | M6: EGIS UK - CONSULTING AND ENGINEERING LIMITED Billable | N6: =_xlfn.XLOOKUP(M6,'source template'!A:A,'source template'!I:I,,1) -> 0 | V6: GBP | X6: Corporate | Y6: T | Z6: FALSE | AA6: FALSE | AB6: TRUE | AD6: Budget | AE6: P02 | AG6: FINANCIAL | BN6: 47848 | BO6: 44927 | BP6: ZZZZZ | BQ6: STD | BR6: Standard | CG6: 47848 | CH6: P02 | CI6: 44927 | CJ6: PJF_TASKS | CK6: FINANCIAL
B7: OK | D7: CREATE | E7: BIL-1007342 | F7: TESTUK1 | G7: ETS-BIL-1007342-TESTUK1 | H7: DRAFT | I7: EGIS UK - CONSULTING AND ENGINEERING LIMITED | J7: =_xlfn.XLOOKUP(I7,LE!A:A,LE!F:F,,1) -> 0 | K7: SL-Nuclear SL-CC-12-NTAI-21-Nuclear Technical Assistance-BU-GB03958GB_EGIS UK | L7: =_xlfn.XLOOKUP(K7,'ORG name (PPM)'!A:A,'ORG name (PPM)'!G:G,,1) -> 0 | M7: EGIS UK - CONSULTING AND ENGINEERING LIMITED Billable | N7: =_xlfn.XLOOKUP(M7,'source template'!A:A,'source template'!I:I,,1) -> 0 | V7: GBP | X7: Corporate | Y7: T | Z7: FALSE | AA7: FALSE | AB7: TRUE | AD7: Non charegable to client | AE7: P03 | AG7: FINANCIAL | BN7: 47848 | BO7: 44927 | BP7: ZZZZZ | BQ7: STD | BR7: Standard | CG7: 47848 | CH7: P03 | CI7: 44927 | CJ7: PJF_TASKS | CK7: FINANCIAL
B8: OK | D8: CREATE | E8: BIL-1007342 | F8: TESTUK1 | G8: ETS-BIL-1007342-TESTUK1 | H8: DRAFT | I8: EGIS UK - CONSULTING AND ENGINEERING LIMITED | J8: =_xlfn.XLOOKUP(I8,LE!A:A,LE!F:F,,1) -> 0 | K8: SL-Nuclear SL-CC-12-NTAI-21-Nuclear Technical Assistance-BU-GB03958GB_EGIS UK | L8: =_xlfn.XLOOKUP(K8,'ORG name (PPM)'!A:A,'ORG name (PPM)'!G:G,,1) -> 0 | M8: EGIS UK - CONSULTING AND ENGINEERING LIMITED Billable | N8: =_xlfn.XLOOKUP(M8,'source template'!A:A,'source template'!I:I,,1) -> 0 | V8: GBP | X8: Corporate | Y8: T | Z8: FALSE | AA8: FALSE | AB8: TRUE | AD8: 425770 - Egis Structures and Environment - CM | AE8: P04 | AG8: FINANCIAL | BN8: 47848 | BO8: 44927 | BP8: ZZZZZ | BQ8: STD | BR8: Standard | CG8: 47848 | CH8: P04 | CI8: 44927 | CJ8: PJF_TASKS | CK8: FINANCIAL
B9: OK | D9: CREATE | E9: BIL-1007342 | F9: TESTUK1 | G9: ETS-BIL-1007342-TESTUK1 | H9: DRAFT | I9: EGIS UK - CONSULTING AND ENGINEERING LIMITED | J9: =_xlfn.XLOOKUP(I9,LE!A:A,LE!F:F,,1) -> 0 | K9: SL-Nuclear SL-CC-12-NTAI-21-Nuclear Technical Assistance-BU-GB03958GB_EGIS UK | L9: =_xlfn.XLOOKUP(K9,'ORG name (PPM)'!A:A,'ORG name (PPM)'!G:G,,1) -> 0 | M9: EGIS UK - CONSULTING AND ENGINEERING LIMITED Billable | N9: =_xlfn.XLOOKUP(M9,'source template'!A:A,'source template'!I:I,,1) -> 0 | V9: GBP | X9: Corporate | Y9: T | Z9: FALSE | AA9: FALSE | AB9: TRUE | AD9: P05 - Phase 05 | AE9: P05 | AG9: FINANCIAL | BN9: 47848 | BO9: 44927 | BP9: ZZZZZ | BQ9: STD | BR9: Standard | CG9: 47848 | CH9: P05 | CI9: 44927 | CJ9: PJF_TASKS | CK9: FINANCIAL
E10: GB03952GB-IBESDIR1TC | F10: FRA > EGIS Structures and Environment [3952_IBESDIR1TC] | G10: ETS-GB03952GB-IBESDIR1TC-FRA > EGIS Structures and Environment [3952_IBESDIR1TC] | H10: ACTIVE | I10: EGIS TRANSPORT SOLUTIONS LIMITED | J10: =_xlfn.XLOOKUP(I10,LE!A:A,LE!F:F,,1) -> EGIS UK - CONSULTING AND ENGINEERING LIMITED | K10: SL-Advisory Direct-CC-19-AMAN-21-Asset Management Advisory-BU-GB03952GB_ETS | L10: =_xlfn.XLOOKUP(K10,'ORG name (PPM)'!A:A,'ORG name (PPM)'!G:G,,1) -> SL-Advisory Direct-CC-19-AMAN-21-Asset Management Advisory-BU-GB03958GB_EGIS UK | M10: EGIS TRANSPORT SOLUTIONS LIMITED Billable | N10: =_xlfn.XLOOKUP(M10,'source template'!A:A,'source template'!I:I,,1) -> EGIS UK - CONSULTING AND ENGINEERING LIMITED Billable | V10: GBP | X10: Corporate | Y10: T | Z10: FALSE | AA10: FALSE | AB10: TRUE | AS10: Jonathan.ANTHONY@egis-group.com | AT10: Project Manager | AU10: 45716 | BN10: 47848 | BO10: 44927 | BP10: ZZZZZ | BQ10: STD | BR10: Standard
E11: GB03952GB-IBESDIR1TC | F11: FRA > EGIS Structures and Environment [3952_IBESDIR1TC] | G11: GB03952GB-GB03952GB-IBESDIR1TC-FRA > EGIS Structures and Environment [3952_IBESDIR1TC] | H11: ACTIVE | I11: EGIS TRANSPORT SOLUTIONS LIMITED | J11: =_xlfn.XLOOKUP(I11,LE!A:A,LE!F:F,,1) -> EGIS UK - CONSULTING AND ENGINEERING LIMITED | K11: SL-Advisory Direct-CC-19-AMAN-21-Asset Management Advisory-BU-GB03952GB_ETS | L11: =_xlfn.XLOOKUP(K11,'ORG name (PPM)'!A:A,'ORG name (PPM)'!G:G,,1) -> SL-Advisory Direct-CC-19-AMAN-21-Asset Management Advisory-BU-GB03958GB_EGIS UK | M11: EGIS TRANSPORT SOLUTIONS LIMITED Billable | N11: =_xlfn.XLOOKUP(M11,'source template'!A:A,'source template'!I:I,,1) -> EGIS UK - CONSULTING AND ENGINEERING LIMITED Billable | V11: GBP | X11: Corporate | Y11: T | Z11: FALSE | AA11: FALSE | AB11: TRUE | AS11: Joy.WILLIAMS@egis-group.com | AT11: Team Member | AU11: 45790 | BN11: 47848 | BO11: 44927 | BP11: ZZZZZ | BQ11: STD | BR11: Standard
E12: BIL-1007981 | F12: GB03952GB-GB03952GB-PAVSAU1006-SAU > Matarat Asset Management Support [3952_PAVSAU1006] | G12: GB03952GB-PAVSAU1006-SAU > Matarat Asset Management Support [3952_PAVSAU1006] | H12: DRAFT | I12: EGIS UK - CONSULTING AND ENGINEERING LIMITED | J12: =_xlfn.XLOOKUP(I12,LE!A:A,LE!F:F,,1) -> 0 | K12: SL-Advisory Direct-CC-19-AMAN-21-Asset Management Advisory-BU-GB03958GB_EGIS UK | L12: =_xlfn.XLOOKUP(K12,'ORG name (PPM)'!A:A,'ORG name (PPM)'!G:G,,1) -> 0 | M12: EGIS UK - CONSULTING AND ENGINEERING LIMITED Billable | N12: =_xlfn.XLOOKUP(M12,'source template'!A:A,'source template'!I:I,,1) -> 0 | V12: GBP | X12: Corporate | Y12: T | Z12: FALSE | AA12: FALSE | AB12: TRUE | AC12: TRUE | AD12: Tender Costs | AE12: P01 | AG12: FINANCIAL | BN12: 47848 | BO12: 44927 | BP12: 952-000716 | BQ12: STD | BR12: Standard | CG12: 47848 | CH12: P01 | CI12: 44927 | CJ12: PJF_TASKS | CK12: FINANCIAL
E13: CRA-1000030 | F13: Cost Re-Allocation for FR03319FR_EGIS BAT ANT GUY | H13: ACTIVE | I13: EGIS BATIMENTS ANTILLES GUYANE | K13: SL-Shared Services FIN-CC-04-FINA-BL-Accounting BL-BU-FR03319FR_EGIS BAT ANT GUY | M13: EGIS BATIMENTS ANTILLES GUYANE Indirect | V13: EUR | X13: Corporate | Y13: T | Z13: FALSE | AA13: FALSE | AB13: TRUE | AC13: TRUE | AD13: Cost Re-Allocation | AE13: 1 | AF13: CRA-1000030 | AG13: FINANCIAL | BN13: 69763 | BO13: 45292 | BQ13: STD | BR13: Standard | CG13: 69763 | CH13: 1 | CI13: 45292 | CJ13: PJF_TASKS | CK13: FINANCIAL
E14: CRA-1000030 | F14: Cost Re-Allocation for FR03319FR_EGIS BAT ANT GUY | H14: ACTIVE | I14: EGIS BATIMENTS ANTILLES GUYANE | K14: SL-Shared Services FIN-CC-04-FINA-BL-Accounting BL-BU-FR03319FR_EGIS BAT ANT GUY | M14: EGIS BATIMENTS ANTILLES GUYANE Indirect | V14: EUR | X14: Corporate | Y14: T | Z14: FALSE | AA14: FALSE | AB14: TRUE | AC14: TRUE | AV14: Project Classification | AW14: Cost Re-Allocation | BN14: 69763 | BO14: 45292 | BQ14: STD | BR14: Standard
B15: OK | D15: CREATE | E15: BIL-1007983 | F15: TESTME-FR03319FR-4896-30 Logements Siguy [3319_4896] | G15: TESTME--TESTME-FR03319FR-4896-30 Logements Siguy [3319_4896] | H15: DRAFT | I15: EGIS BATIMENTS ILE DE FRANCE | J15: =_xlfn.XLOOKUP(I15,LE!A:A,LE!F:F,,1) -> 0 | K15: SL-Buildings-CC-12-IDMI-01-Ile de France-BU-FR03305FR_EGIS BAT IDF | L15: SL-Buildings-CC-12-IDMI-01-Ile de France-BU-FR03305FR_EGIS BAT IDF | M15: EGIS BATIMENTS ILE DE FRANCE Billable E&SC Small Project | N15: =_xlfn.XLOOKUP(M15,'source template'!A:A,'source template'!I:I,,1) -> 0 | V15: EUR | X15: Corporate | Y15: T | Z15: FALSE | AA15: FALSE | AB15: TRUE | AC15: TRUE | AD15: O | AE15: P01 | AG15: FINANCIAL | BN15: 46203 | BO15: 41275 | BP15: 319-000008 | BQ15: STD | BR15: Standard | CG15: 45657 | CH15: P01 | CI15: 41275 | CJ15: PJF_TASKS | CK15: FINANCIAL
B16: OK | D16: CREATE | E16: BIL-1007983 | F16: TESTME-FR03319FR-4896-30 Logements Siguy [3319_4896] | G16: TESTME--TESTME-FR03319FR-4896-30 Logements Siguy [3319_4896] | H16: DRAFT | I16: EGIS BATIMENTS ILE DE FRANCE | J16: =_xlfn.XLOOKUP(I16,LE!A:A,LE!F:F,,1) -> 0 | K16: SL-Buildings-CC-12-IDMI-01-Ile de France-BU-FR03305FR_EGIS BAT IDF | L16: SL-Buildings-CC-12-IDMI-01-Ile de France-BU-FR03305FR_EGIS BAT IDF | M16: EGIS BATIMENTS ILE DE FRANCE Billable E&SC Small Project | N16: =_xlfn.XLOOKUP(M16,'source template'!A:A,'source template'!I:I,,1) -> 0 | V16: EUR | X16: Corporate | Y16: T | Z16: FALSE | AA16: FALSE | AB16: TRUE | AC16: TRUE | AD16: E | AE16: P02 | AG16: FINANCIAL | BN16: 46203 | BO16: 41275 | BP16: 319-000008 | BQ16: STD | BR16: Standard | CG16: 45688 | CH16: P02 | CI16: 41275 | CJ16: PJF_TASKS | CK16: FINANCIAL
B17: OK | D17: CREATE | E17: BIL-1007983 | F17: TESTME-FR03319FR-4896-30 Logements Siguy [3319_4896] | G17: TESTME--TESTME-FR03319FR-4896-30 Logements Siguy [3319_4896] | H17: DRAFT | I17: EGIS BATIMENTS ILE DE FRANCE | J17: =_xlfn.XLOOKUP(I17,LE!A:A,LE!F:F,,1) -> 0 | K17: SL-Buildings-CC-12-IDMI-01-Ile de France-BU-FR03305FR_EGIS BAT IDF | L17: SL-Buildings-CC-12-IDMI-01-Ile de France-BU-FR03305FR_EGIS BAT IDF | M17: EGIS BATIMENTS ILE DE FRANCE Billable E&SC Small Project | N17: =_xlfn.XLOOKUP(M17,'source template'!A:A,'source template'!I:I,,1) -> 0 | V17: EUR | X17: Corporate | Y17: T | Z17: FALSE | AA17: FALSE | AB17: TRUE | AC17: TRUE | AD17: T | AE17: P03 | AG17: FINANCIAL | BN17: 46203 | BO17: 41275 | BP17: 319-000008 | BQ17: STD | BR17: Standard | CG17: 46203 | CH17: P03 | CI17: 41275 | CJ17: PJF_TASKS | CK17: FINANCIAL
B18: OK | D18: CREATE | E18: BIL-1007983 | F18: TESTME-FR03319FR-4896-30 Logements Siguy [3319_4896] | G18: TESTME--TESTME-FR03319FR-4896-30 Logements Siguy [3319_4896] | H18: DRAFT | I18: EGIS BATIMENTS ILE DE FRANCE | J18: =_xlfn.XLOOKUP(I18,LE!A:A,LE!F:F,,1) -> 0 | K18: SL-Buildings-CC-12-IDMI-01-Ile de France-BU-FR03305FR_EGIS BAT IDF | L18: SL-Buildings-CC-12-IDMI-01-Ile de France-BU-FR03305FR_EGIS BAT IDF | M18: EGIS BATIMENTS ILE DE FRANCE Billable E&SC Small Project | N18: =_xlfn.XLOOKUP(M18,'source template'!A:A,'source template'!I:I,,1) -> 0 | V18: EUR | X18: Corporate | Y18: T | Z18: FALSE | AA18: FALSE | AB18: TRUE | AC18: TRUE | AD18: Facturation Milestone Oracle 2025 | AE18: P97 | AG18: FINANCIAL | BN18: 46203 | BO18: 41275 | BP18: 319-000008 | BQ18: STD | BR18: Standard | CG18: 46022 | CH18: P97 | CI18: 41275 | CJ18: PJF_TASKS | CK18: FINANCIAL
B19: OK | D19: CREATE | E19: BIL-1007983 | F19: TESTME-FR03319FR-4896-30 Logements Siguy [3319_4896] | G19: TESTME--TESTME-FR03319FR-4896-30 Logements Siguy [3319_4896] | H19: DRAFT | I19: EGIS BATIMENTS ILE DE FRANCE | J19: =_xlfn.XLOOKUP(I19,LE!A:A,LE!F:F,,1) -> 0 | K19: SL-Buildings-CC-12-IDMI-01-Ile de France-BU-FR03305FR_EGIS BAT IDF | L19: SL-Buildings-CC-12-IDMI-01-Ile de France-BU-FR03305FR_EGIS BAT IDF | M19: EGIS BATIMENTS ILE DE FRANCE Billable E&SC Small Project | N19: =_xlfn.XLOOKUP(M19,'source template'!A:A,'source template'!I:I,,1) -> 0 | V19: EUR | X19: Corporate | Y19: T | Z19: FALSE | AA19: FALSE | AB19: TRUE | AC19: TRUE | AV19: Project Classification | AW19: Client Project | BN19: 46203 | BO19: 41275 | BP19: 319-000008 | BQ19: STD | BR19: Standard
B20: OK | D20: CREATE | E20: BIL-1007983 | F20: TESTME-FR03319FR-4896-30 Logements Siguy [3319_4896] | G20: TESTME--TESTME-FR03319FR-4896-30 Logements Siguy [3319_4896] | H20: DRAFT | I20: EGIS BATIMENTS ILE DE FRANCE | J20: =_xlfn.XLOOKUP(I20,LE!A:A,LE!F:F,,1) -> 0 | K20: SL-Buildings-CC-12-IDMI-01-Ile de France-BU-FR03305FR_EGIS BAT IDF | L20: SL-Buildings-CC-12-IDMI-01-Ile de France-BU-FR03305FR_EGIS BAT IDF | M20: EGIS BATIMENTS ILE DE FRANCE Billable E&SC Small Project | N20: =_xlfn.XLOOKUP(M20,'source template'!A:A,'source template'!I:I,,1) -> 0 | V20: EUR | X20: Corporate | Y20: T | Z20: FALSE | AA20: FALSE | AB20: TRUE | AC20: TRUE | AS20: Etienne.FERRER@egis-group.com | AT20: Project Manager | AU20: 43864 | BN20: 46203 | BO20: 41275 | BP20: 319-000008 | BQ20: STD | BR20: Standard
B21: OK | D21: CREATE | E21: BIL-1007983 | F21: TESTME-FR03319FR-4896-30 Logements Siguy [3319_4896] | G21: TESTME--TESTME-FR03319FR-4896-30 Logements Siguy [3319_4896] | H21: DRAFT | I21: EGIS BATIMENTS ILE DE FRANCE | J21: =_xlfn.XLOOKUP(I21,LE!A:A,LE!F:F,,1) -> 0 | K21: SL-Buildings-CC-12-IDMI-01-Ile de France-BU-FR03305FR_EGIS BAT IDF | L21: SL-Buildings-CC-12-IDMI-01-Ile de France-BU-FR03305FR_EGIS BAT IDF | M21: EGIS BATIMENTS ILE DE FRANCE Billable E&SC Small Project | N21: =_xlfn.XLOOKUP(M21,'source template'!A:A,'source template'!I:I,,1) -> 0 | V21: EUR | X21: Corporate | Y21: T | Z21: FALSE | AA21: FALSE | AB21: TRUE | AC21: TRUE | AS21: Rokhaya.NDIAYE@egis-group.com | AT21: Financial Controller | AU21: 41883 | BN21: 46203 | BO21: 41275 | BP21: 319-000008 | BQ21: STD | BR21: Standard
B22: OK | D22: CREATE | E22: BIL-1007983 | F22: TESTME-FR03319FR-4896-30 Logements Siguy [3319_4896] | G22: TESTME--TESTME-FR03319FR-4896-30 Logements Siguy [3319_4896] | H22: DRAFT | I22: EGIS BATIMENTS ILE DE FRANCE | J22: =_xlfn.XLOOKUP(I22,LE!A:A,LE!F:F,,1) -> 0 | K22: SL-Buildings-CC-12-IDMI-01-Ile de France-BU-FR03305FR_EGIS BAT IDF | L22: SL-Buildings-CC-12-IDMI-01-Ile de France-BU-FR03305FR_EGIS BAT IDF | M22: EGIS BATIMENTS ILE DE FRANCE Billable E&SC Small Project | N22: =_xlfn.XLOOKUP(M22,'source template'!A:A,'source template'!I:I,,1) -> 0 | V22: EUR | X22: Corporate | Y22: T | Z22: FALSE | AA22: FALSE | AB22: TRUE | AC22: TRUE | AS22: Sebastien.PLICHON@egis-group.com | AT22: RBLD | AU22: 42736 | BN22: 46203 | BO22: 41275 | BP22: 319-000008 | BQ22: STD | BR22: Standard
B23: OK | D23: CREATE | E23: BIL-1007983 | F23: TESTME-FR03319FR-4896-30 Logements Siguy [3319_4896] | G23: TESTME--TESTME-FR03319FR-4896-30 Logements Siguy [3319_4896] | H23: DRAFT | I23: EGIS BATIMENTS ILE DE FRANCE | J23: =_xlfn.XLOOKUP(I23,LE!A:A,LE!F:F,,1) -> 0 | K23: SL-Buildings-CC-12-IDMI-01-Ile de France-BU-FR03305FR_EGIS BAT IDF | L23: SL-Buildings-CC-12-IDMI-01-Ile de France-BU-FR03305FR_EGIS BAT IDF | M23: EGIS BATIMENTS ILE DE FRANCE Billable E&SC Small Project | N23: =_xlfn.XLOOKUP(M23,'source template'!A:A,'source template'!I:I,,1) -> 0 | V23: EUR | X23: Corporate | Y23: T | Z23: FALSE | AA23: FALSE | AB23: TRUE | AC23: TRUE | AS23: Cedric.ARNAUD@egis-group.com | AT23: Project Sponsor / RBLD Delegate | AU23: 45680 | BN23: 46203 | BO23: 41275 | BP23: 319-000008 | BQ23: STD | BR23: Standard
B24: OK | D24: CREATE | E24: BIL-1007983 | F24: TESTME-FR03319FR-4896-30 Logements Siguy [3319_4896] | G24: TESTME--TESTME-FR03319FR-4896-30 Logements Siguy [3319_4896] | H24: DRAFT | I24: EGIS BATIMENTS ILE DE FRANCE | J24: =_xlfn.XLOOKUP(I24,LE!A:A,LE!F:F,,1) -> 0 | K24: SL-Buildings-CC-12-IDMI-01-Ile de France-BU-FR03305FR_EGIS BAT IDF | L24: SL-Buildings-CC-12-IDMI-01-Ile de France-BU-FR03305FR_EGIS BAT IDF | M24: EGIS BATIMENTS ILE DE FRANCE Billable E&SC Small Project | N24: =_xlfn.XLOOKUP(M24,'source template'!A:A,'source template'!I:I,,1) -> 0 | V24: EUR | X24: Corporate | Y24: T | Z24: FALSE | AA24: FALSE | AB24: TRUE | AC24: TRUE | AS24: Benoit.THERON@egis-group.com | AT24: Project Manager | AU24: 45804 | BN24: 46203 | BO24: 41275 | BP24: 319-000008 | BQ24: STD | BR24: Standard
B25: OK | D25: CREATE | E25: BIL-1007983 | F25: TESTME-FR03319FR-4896-30 Logements Siguy [3319_4896] | G25: TESTME--TESTME-FR03319FR-4896-30 Logements Siguy [3319_4896] | H25: DRAFT | I25: EGIS BATIMENTS ILE DE FRANCE | J25: =_xlfn.XLOOKUP(I25,LE!A:A,LE!F:F,,1) -> 0 | K25: SL-Buildings-CC-12-IDMI-01-Ile de France-BU-FR03305FR_EGIS BAT IDF | L25: SL-Buildings-CC-12-IDMI-01-Ile de France-BU-FR03305FR_EGIS BAT IDF | M25: EGIS BATIMENTS ILE DE FRANCE Billable E&SC Small Project | N25: =_xlfn.XLOOKUP(M25,'source template'!A:A,'source template'!I:I,,1) -> 0 | V25: EUR | X25: Corporate | Y25: T | Z25: FALSE | AA25: FALSE | AB25: TRUE | AC25: TRUE | AS25: Cedric.ARNAUD@egis-group.com | AT25: Project Manager | AU25: 45658 | BN25: 46203 | BO25: 41275 | BP25: 319-000008 | BQ25: STD | BR25: Standard
